Workbook

Sheet LISEZ-MOI
A1: Foyer Zéro — les onze bâtiments de la base du joueur
A2: Relevé au 25/08/2026. État réel de ce qui est connu, et de ce qui ne l'est pas.
A4: Réponse courte à la question posée
A5: NON, les données exactes n'existent pas. Sur les quatre colonnes demandées :
A6: • RÔLE — connu pour 11 sur 11, dont 4 nommés seulement à l'oral.
A7: • EFFET, en texte — connu pour 11 sur 11.
A8: • STAT DE BASE (PV, temps de réparation) — connue pour 11 sur 11, mais TRANSPOSÉE de
A9: Tiberium Alliances, jamais arbitrée pour Foyer Zéro. Précédent fort : les cinq
A10: bâtiments de site de src/data/sites.js reprennent ces mêmes PV à l'identique.
A11: • EFFET CHIFFRÉ (production, stockage, coûts, électricité) — MANQUANT presque partout.
A12: C'est le vrai trou : voir l'onglet TROUS, quatorze lignes.
A14: Ce que ce classeur est, et n'est pas
... A57: abandon du pack de ressources

Sheet BATIMENTS
A1: Les onze bâtiments de la base du joueur
A2: Nom, rôle et effet : FOYER-ZERO-LEXIQUE.xlsx via BASE-DU-JOUEUR-1.md. PV et réparation : RELEVE-TA-COURBES-2.md §6.5, valeurs de NIVEAU 1, transposées de TA.
A4: id proposé | B4: Nom joueur | C4: Nom Ouvrage | D4: Nom TA | E4: Rôle | F4: Effet | G4: PV niv. 1 | H4: Répar. base (s) | I4: Unicité | J4: Statut du nom
A5: chantierDeConstruction | B5: Chantier de construction | C5: Souche | D5: Construction Yard | E5: central | F5: Central du joueur. Commande le TEMPS de réparation des bâtiments. Seul bâtiment sans plancher de PV : sa chute rase la base. | G5: 5500 | H5: 88 | I5: oui | J5: ABSENT du lexique — nom TA faute de mieux | K5: propose mieux comme nom joueur, sinon inscrire dans le lexique
A6: centreDeCommandement | B6: Centre de commandement | C6: — | D6: Command Center | E6: QG offensif | F6: Points d'armée offensifs + plafond de niveau des unités offensives. | G6: 3000 | H6: 88 | I6: oui | J6: nommé
A7: qgDeDefense | B7: QG de défense | C7: — | D7: Defense HQ | E7: QG défensif | F7: Points d'armée défensifs + plafond de niveau des défenses. | G7: 3000 | H7: 88 | I7: oui | J7: nommé
A8: complexeDeDefense | B8: Complexe de défense | C8: Étai | D8: Defense Facility | E8: réparation | F8: Répare TOUTES les défenses, gratuitement, en une heure. Son niveau commande la disponibilité ; sa perte bloque la réparation. | G8: 2500 | H8: 88 | I8: oui | J8: nommé
A9: caserne | B9: Caserne | C9: — | D9: Barracks | E9: production · escouade | F9: Accès aux escouades et vitesse de leur réparation. | G9: 2500 | H9: 88 | I9: oui | J9: ABSENT du lexique — nommé à l'oral le 24/08 | K9: nom à inscrire dans lexique
A10: depotDeVehicules | B10: Dépôt de véhicules | C10: — | D10: Factory | E10: production · blindé | F10: Accès aux blindés et vitesse de leur réparation. | G10: 2500 | H10: 88 | I10: oui | J10: ABSENT du lexique — nommé à l'oral le 24/08 | K10: nom à inscrire dans lexique
A11: aerodrome | B11: Aérodrome | C11: — | D11: Airfield | E11: production · aéronef | F11: Accès aux aéronefs et vitesse de leur réparation. | G11: 2500 | H11: 88 | I11: oui | J11: ABSENT du lexique — nommé à l'oral le 24/08 | K11: nom à inscrire dans lexique
A12: centrale | B12: Centrale | C12: — | D12: Power Plant | E12: production · électricité | F12: Produit l'électricité par COLIS, plus un flux CONTINU fonction des champs de scorie voisins. | G12: 2000 | H12: 65 | I12: non | J12: nommé (minuscule dans le lexique)
A13: collecteur | B13: Collecteur | C13: Nœud | D13: Harvester | E13: production · ressources | F13: Produit quartz ou scorie par COLIS. | G13: 1500 | H13: 65 | I13: non | J13: nommé (minuscule dans le lexique)
A14: raffinerie | B14: Raffinerie | C14: Gangue | D14: Tiberium Silo | E14: stockage · ressources | F14: Stocke les ressources et en produit un flux CONTINU fonction du nombre de collecteurs voisins. | G14: 1000 | H14: 42 | I14: non | J14: COLLISION — « Raffinerie » nomme aussi la Gangue de site | K14: euh, on s'en fout ?
A15: accumulateur | B15: Accumulateur | C15: — | D15: Accumulator | E15: stockage · électricité | F15: Stocke l'électricité et en produit un flux CONTINU fonction du nombre de centrales voisines. | G15: 1000 | H15: 42 | I15: non | J15: nommé (minuscule dans le lexique)
A16: TOTAL | F16: PV cumulés d'une base niveau 1 | G16: =SUM(G5:G15) -> 27000
A18: · Les quatre « ABSENT du lexique » sont ceux de BASE-DU-JOUEUR-1.md §2. Ethan les a nommés à l'oral le 24/08 ; ils n'ont pas de nom Foyer Zéro écrit.
A19: · Le Chantier de construction porte encore son nom TA. C'est aussi le seul bâtiment SANS plancher de PV (MODELE-REPARATION-1.md §2) : sa chute rase la base.
A20: · « Répar. base » est le temps de réparation du BÂTIMENT lui-même, en secondes, au niveau 1. 88 s = 1:28, 65 s = 1:05, 42 s = 0:42 (RELEVE-TA-COURBES-2.md §6.5).
A21: · Ne pas confondre avec le temps de réparation des UNITÉS, que ces bâtiments commandent et dont la formule est au §4 du même relevé : T(L,C) = base_unité × 1,15^(L−1) / D(C).
A22: · Les trois bâtiments de production — Caserne, dépôt, aérodrome — partagent 2 500 PV chez TA : une seule ligne les couvre là-bas, trois ici.
A23: · La colonne « Nom Ouvrage » n'a de valeur que pour trois d'entre eux : l'Ouvrage n'a ni Centre de commandement, ni QG de défense, ni base au sens du joueur (SPEC §7).

Sheet EFFETS
A1: L'effet chiffré — ce qui est arbitré, ce qui vient de TA, ce qui manque
A2: Trois colonnes de statut. ARBITRÉ = décidé pour Foyer Zéro et vivant dans src/data/. TA = relevé chez Tiberium Alliances, jamais arbitré. MANQUANT = à remplir, fond jaune.
A4: Bâtiment | B4: Grandeur | C4: Statut | D4: Valeur Foyer Zéro | E4: Valeur TA relevée | F4: Source / remarque
A5: — EXEMPLE — | B5: ligne de démonstration du format attendu | C5: ARBITRÉ | D5: 1,5 unité / minute au niveau 1 | E5: 1 unité / minute | F5: Exemple : une valeur, son unité, le niveau auquel elle s'applique. À supprimer une fois le classeur rempli.
A6: Centre de commandement | B6: Points d'armée offensifs | C6: ARBITRÉ | D6: 20 + 5 × niveau (45 au niv. 1, 290 au niv. 50) | E6: 10, plat | F6: src/data/sites.js — POINTS_ARMEE.offense. TA donnait un plat, Foyer Zéro en fait une droite.
A7: Centre de commandement | B7: Plafond de niveau des unités | C7: MANQUANT | D7: niv unité max = niv centre commandement (erreur de calcul au dessus, c'est 25 niv 1 ) | E7: plafond = niveau du bâtiment | F7: COURBE-DE-NIVEAU-2.md §4 : c'est LE paramètre qui décide d'un raid (+1 niveau = ×1,74 en combat).
A8: QG de défense | B8: Points d'armée défensifs | C8: ARBITRÉ | D8: 40 + 5 × niveau (45 au niv. 1, 290 au niv. 50) | E8: 20, plat | F8: src/data/sites.js — POINTS_ARMEE.defense.
A9: QG de défense | B9: Plafond de niveau des défenses | C9: MANQUANT | D9: idem TA | E9: plafond = niveau du bâtiment | F9: MODELE-REPARATION-1.md §3 : monter les défenses au-delà du Complexe est permis — puissance contre disponibilité.
A10: Complexe de défense | B10: Part des PV réparés | C10: non | D10: 70% instantané, puis de 0% à 100% en 1h cf lisez moi Claude | E10: 70 % des PV perdus | F10: MODELE-REPARATION-1.md §3. ⚠ Les 70 % restent écrits dans le lexique, la spec §1 et §2 : périmés.
A11: Complexe de défense | B11: Temps de réparation des défenses | C11: ARBITRÉ | D11: 1 heure, plancher — davantage si les défenses dépassent son niveau | E11: — | F11: MODELE-REPARATION-1.md §3. La FORMULE du dépassement manque : voir TROUS.
A12: Complexe de défense | B12: Coût de réparation des défenses | C12: ARBITRÉ | D12: gratuit | E12: — | F12: MODELE-REPARATION-1.md §3. La défense n'est financée par rien, des deux côtés.
A13: Chantier de construction | B13: Emplacements de base | C13: MANQUANT | D13: 2 par niveau jusqu'au niveau 10, puis 1 par niveau jusqu'à 40 max | E13: 4 emplacements | F13: RELEVE-TA-COURBES-2.md §6.5. Rien ne dit si Foyer Zéro garde une notion d'emplacement.
A14: Chantier de construction | B14: Stockage propre | C14: MANQUANT | D14: valeur TA | E14: 50 tib. + 50 cristal + 40 énergie | F14: RELEVE-TA-COURBES-2.md §6.5.
A15: Chantier de construction | B15: Effet sur le temps de réparation | C15: MANQUANT | D15: valeur ta | E15: D(C) = 1,09^(min(C,12)−1) × 1,12^max(C−12,0) | F15: RELEVE-TA-COURBES-2.md §4 — mesuré. C'est le diviseur du temps ; reste à décider s'il vaut pour les bâtiments comme pour les unités.
... A19: Centrale | B19: Flux continu selon les champs de scorie | C19: MANQUANT | D19: base niv 1 : 60/h puis x1,25 par niveau de la centrale, par champs de scories à proximité immédiate (8 cases autours) | E19: n'existe pas chez TA | F19: BASE-DU-JOUEUR-1.md §1 et §3. Voisinage TYPÉ : il faut le rayon, le bonus par champ, et le plafond de voisins.
A20: centrale | B20: flux continu selon accu à proximité en plus du flux accu | D20: base niv 1 : 72/h puis x1,25 par niveau de la centrale, par accumulateur à proximité immédiate
A21: Accumulateur | B21: Stockage d'électricité | C21: MANQUANT | D21: base niv 1 : 15. courbe TA atroce et différente des autres, je propose x2 jusqu'au niv 10, puis on courbe pour atteindre x1,333 au niv 50 | E21: 15 énergie | F21: RELEVE-TA-COURBES-2.md §6.5.
A22: Accumulateur | B22: Flux continu selon les centrales voisines | C22: MANQUANT | D22: base niv 1 : 48/h puis x1,25 par niveau de l'accu, par centrale à proximité immédiate | E22: n'existe pas chez TA | F22: BASE-DU-JOUEUR-1.md §1. Le socle existe : params.js — adjacence.facteur 0,5 × P(1), 2 voisins au plus. Il n'est pas typé.
A23: Collecteur | B23: Production continue | C23: ARBITRÉ | D23: base niv 1 : 240/h puis x1,25 par niveau du collecteur | E23: 4 ressources / minute par paquet | F23: src/data/params.js — colis. Le RENDEMENT par colis, lui, manque.
A24: Collecteur | B24: Flux continu, niveau 1 | C24: ARBITRÉ | D24: base niv 1 : 72/h puis x1,25 par niveau du collecteur, par raffinerie à proximité immédiate (8 cases autours) | E24: — | F24: src/data/params.js — fluxContinu.baseMilliParTickNiveau1. Entier obligatoire : l'économie par tick est en arithmétique entière.
A25: Collecteur | B25: Indice de butin quand on le pille | C25: ARBITRÉ | D25: indice 2 | E25: indice 2,75 — la cible la plus rentable | F25: src/data/sites.js — BATIMENTS.noeud. RELEVE-TA-ECONOMIE.md §1 donne 2,75 ; Foyer Zéro a retenu 2.
A26: Raffinerie | B26: Capacité de stockage | C26: ARBITRÉ | D26: base niv 1 : 20 courbe TA atroce et différente des autres, je propose x2 jusqu'au niv 10, puis on courbe pour atteindre x1,333 au niv 50 | E26: 20 tibérium / cristal | F26: src/data/params.js — stockage.capaciteMilli. Le flux continu s'arrête stockage plein.
A27: Raffinerie | B27: Flux continu selon les collecteurs voisins | C27: MANQUANT | D27: base niv 1 : 72/h puis x1,25 par niveau de la raffinerie, par collecteur à proximité immédiate | E27: n'existe pas chez TA | F27: BASE-DU-JOUEUR-1.md §1. Même trou que l'Accumulateur : voisinage typé à chiffrer.
A28: Tous | B28: Coût de construction, niveau 1 | C28: MANQUANT | D28: cout niv 1 gratuit. Cout niv 2 (qg def, qg off, chr de construction) 8 quartz ; (caserne, aérodrome, usine, complexe de def) 5 quartz ; centrale collecteur 3 quartz ; raffinerie accumulateur 2 quartz | E28: — | F28: Aucun chiffre. params.js ne porte que foreuse (20) et decapeuse (35), qui sont les bâtiments du lot 1, pas ceux-ci.
A29: Tous | B29: Coût de montée niveau n → n+1 | C29: ARBITRÉ | D29: à partir du niv 2 : x1,25, x2, x4, x5,5, x3,2727.., x3,0555.., x 2,9090..., x2,75, x2,5454..., x2,142, x1,32 pour tout les suivants | E29: ×1,794 de 10 à 11, puis ×1,32 | F29: COURBE-DE-NIVEAU-2.md §3 et RELEVE-TA-COURBES-2.md §5. ⚠ La rupture réelle est au niveau 11, pas 12 : à trancher.
A30: Tous | B30: Coût en électricité d'une amélioration | C30: MANQUANT | D30: niv 3 et plus ; 10% pour la centrale ; 50% pour le collecteur ; 25% pour les autres | E30: le quart de la monnaie principale | F30: RELEVE-TA-COURBES-2.md §5. BASE-DU-JOUEUR-1.md §4 : l'électricité conditionne TOUTES les améliorations, sans exception.
A31: Tous | B31: PV par niveau | C31: TA | D31: PV(1) × courbe — voir onglet COURBE | E31: PV(1) × 1,32^(n−1) | F31: COURBE-DE-NIVEAU-2.md §1 : PV et dégâts partagent la même courbe, c'est ce qui fait tenir le miroir.
A32: Tous | B32: Plancher de PV | C32: ARBITRÉ | D32: 1 PV — sauf le Chantier de construction, qui meurt vraiment | E32: — | F32: MODELE-REPARATION-1.md §1 et §2. ⚠ Ce n'est PAS 1 %, et ce n'est pas une grandeur du moteur de combat : c'est une écriture d'après-raid.
A34: À REMPLIR : uniquement les cellules à fond jaune de la colonne D. La ligne « — EXEMPLE — » montre le format attendu et se supprime ensuite.
C35: niv 2 | D35: 8
C36: niv 3 | D36: 10 | E36: =D36/D35 -> 1.25
C37: niv 4 | D37: 20 | E37: =D37/D36 -> 2
C38: niv 5 | D38: 80 | E38: =D38/D37 -> 4
C39: niv 6 | D39: 440 | E39: =D39/D38 -> 5.5
C40: niv 7 | D40: 1440 | E40: =D40/D39 -> 3.2727273
C41: niv 8 | D41: 4400 | E41: =D41/D40 -> 3.0555556
C42: niv 9 | D42: 12800 | E42: =D42/D41 -> 2.9090909
C43: niv 10 | D43: 35200 | E43: =D43/D42 -> 2.75
C44: niv 11 | D44: 89600 | E44: =D44/D43 -> 2.5454545
C45: niv 12 | D45: 192000 | E45: =D45/D44 -> 2.1428571
...

Sheet COURBE
A1: PV des bâtiments du joueur, par niveau
A2: La question ouverte de COURBE-DE-NIVEAU-2.md §3 : les PV suivent-ils les deux régimes du butin et des coûts, ou ×1,32 partout ? Basculer en B4 pour voir l'écart.
A4: Régime retenu → | B4: deux régimes | C4: saisir « deux régimes » ou « 1,32 partout »
B5: ni l'un ni l'autre, j'ai trouvé la vrai courbe, hyper simple
A6: Constantes
A7: pente basse (niv. 1 → 12) | B7: 1.259 | C7: RELEVE-TA-ECONOMIE.md §1 — deux collecteurs voisins, 3 613 et 4 550
A8: pente haute (au-delà de 12) | B8: 1.32 | C8: RELEVE-TA-ECONOMIE.md §1 — 1,32^11 = 21,196 sur cinq bâtiments indépendants
A9: niveau de rupture | B9: 12 | C9: ⚠ le relevé économique voit la rupture des COÛTS au niveau 11, avec un saut ×1,794 — à trancher
A11: Niveau | B11: Facteur deux régimes | C11: Facteur ×1,32 partout | D11: Facteur retenu | E11: Chantier de construction | F11: Centre de commandement | G11: QG de défense | H11: Complexe de défense | I11: Caserne | J11: Dépôt de véhicules | K11: Aérodrome | L11: Centrale | M11: Collecteur | N11: Raffinerie | O11: Accumulateur
D12: PV niveau 1 → | E12: =BATIMENTS!G5 -> 5500 | F12: =BATIMENTS!G6 -> 3000 | G12: =BATIMENTS!G7 -> 3000 | H12: =BATIMENTS!G8 -> 2500 | I12: =BATIMENTS!G9 -> 2500 | J12: =BATIMENTS!G10 -> 2500 | K12: =BATIMENTS!G11 -> 2500 | L12: =BATIMENTS!G12 -> 2000 | M12: =BATIMENTS!G13 -> 1500 | N12: =BATIMENTS!G14 -> 1000 | O12: =BATIMENTS!G15 -> 1000
A13: 1 | B13: =$B$7^(MIN(A13,$B$9)-1)*$B$8^(MAX(A13-$B$9,0)) -> 1 | C13: =$B$8^(A13-1) -> 1 | D13: 1.1 | E13: =E12*D13 -> 6050 | F13: =F12*$D13 -> 3300 | G13: =G12*$D13 -> 3300 | H13: =H12*$D13 -> 2750 | I13: =I12*$D13 -> 2750 | J13: =J12*$D13 -> 2750 | K13: =K12*$D13 -> 2750 | L13: =L12*$D13 -> 2200 | M13: =M12*$D13 -> 1650 | ... O13: =O12*$D13 -> 1100 | Q13: 5500
A14: 2 | B14: =$B$7^(MIN(A14,$B$9)-1)*$B$8^(MAX(A14-$B$9,0)) -> 1.259 | C14: =$B$8^(A14-1) -> 1.32 | D14: 1.1 | E14: =E13*D14 -> 6655 | F14: =F13*$D14 -> 3630 | G14: =G13*$D14 -> 3630 | H14: =H13*$D14 -> 3025 | I14: =I13*$D14 -> 3025 | J14: =J13*$D14 -> 3025 | K14: =K13*$D14 -> 3025 | L14: =L13*$D14 -> 2420 | M14: =M13*$D14 -> 1815 | ... O14: =O13*$D14 -> 1210 | Q14: 6050 | R14: =Q14/Q13 -> 1.1
A15: 3 | B15: =$B$7^(MIN(A15,$B$9)-1)*$B$8^(MAX(A15-$B$9,0)) -> 1.585081 | C15: =$B$8^(A15-1) -> 1.7424 | D15: 1.1 | E15: =E14*D15 -> 7320.5 | F15: =F14*$D15 -> 3993 | G15: =G14*$D15 -> 3993 | H15: =H14*$D15 -> 3327.5 | I15: =I14*$D15 -> 3327.5 | J15: =J14*$D15 -> 3327.5 | K15: =K14*$D15 -> 3327.5 | L15: =L14*$D15 -> 2662 | M15: =M14*$D15 -> 1996.5 | ... O15: =O14*$D15 -> 1331 | Q15: 6655 | R15: =Q15/Q14 -> 1.1
A16: 4 | B16: =$B$7^(MIN(A16,$B$9)-1)*$B$8^(MAX(A16-$B$9,0)) -> 1.995617 | C16: =$B$8^(A16-1) -> 2.299968 | D16: 1.1 | E16: =E15*D16 -> 8052.55 | F16: =F15*$D16 -> 4392.3 | G16: =G15*$D16 -> 4392.3 | H16: =H15*$D16 -> 3660.25 | I16: =I15*$D16 -> 3660.25 | J16: =J15*$D16 -> 3660.25 | K16: =K15*$D16 -> 3660.25 | L16: =L15*$D16 -> 2928.2 | M16: =M15*$D16 -> 2196.15 | ... O16: =O15*$D16 -> 1464.1 | Q16: 7321 | R16: =Q16/Q15 -> 1.1000751
A17: 5 | B17: =$B$7^(MIN(A17,$B$9)-1)*$B$8^(MAX(A17-$B$9,0)) -> 2.5124818 | C17: =$B$8^(A17-1) -> 3.0359578 | D17: 1.1 | E17: =E16*D17 -> 8857.805 | F17: =F16*$D17 -> 4831.53 | G17: =G16*$D17 -> 4831.53 | H17: =H16*$D17 -> 4026.275 | I17: =I16*$D17 -> 4026.275 | J17: =J16*$D17 -> 4026.275 | K17: =K16*$D17 -> 4026.275 | L17: =L16*$D17 -> 3221.02 | M17: =M16*$D17 -> 2415.765 | ... O17: =O16*$D17 -> 1610.51
A18: 6 | B18: =$B$7^(MIN(A18,$B$9)-1)*$B$8^(MAX(A18-$B$9,0)) -> 3.1632146 | C18: =$B$8^(A18-1) -> 4.0074642 | D18: 1.1 | E18: =E17*D18 -> 9743.5855 | F18: =F17*$D18 -> 5314.683 | G18: =G17*$D18 -> 5314.683 | H18: =H17*$D18 -> 4428.9025 | I18: =I17*$D18 -> 4428.9025 | J18: =J17*$D18 -> 4428.9025 | K18: =K17*$D18 -> 4428.9025 | L18: =L17*$D18 -> 3543.122 | M18: =M17*$D18 -> 2657.3415 | ... O18: =O17*$D18 -> 1771.561
A19: 7 | B19: =$B$7^(MIN(A19,$B$9)-1)*$B$8^(MAX(A19-$B$9,0)) -> 3.9824871 | C19: =$B$8^(A19-1) -> 5.2898528 | D19: 1.1 | E19: =E18*D19 -> 10717.944 | F19: =F18*$D19 -> 5846.1513 | G19: =G18*$D19 -> 5846.1513 | H19: =H18*$D19 -> 4871.7928 | I19: =I18*$D19 -> 4871.7928 | J19: =J18*$D19 -> 4871.7928 | K19: =K18*$D19 -> 4871.7928 | L19: =L18*$D19 -> 3897.4342 | M19: =M18*$D19 -> 2923.0757 | ... O19: =O18*$D19 -> 1948.7171
A20: 8 | B20: =$B$7^(MIN(A20,$B$9)-1)*$B$8^(MAX(A20-$B$9,0)) -> 5.0139513 | C20: =$B$8^(A20-1) -> 6.9826057 | D20: 1.1 | E20: =E19*D20 -> 11789.738 | F20: =F19*$D20 -> 6430.7664 | G20: =G19*$D20 -> 6430.7664 | H20: =H19*$D20 -> 5358.972 | I20: =I19*$D20 -> 5358.972 | J20: =J19*$D20 -> 5358.972 | K20: =K19*$D20 -> 5358.972 | L20: =L19*$D20 -> 4287.1776 | M20: =M19*$D20 -> 3215.3832 | ... O20: =O19*$D20 -> 2143.5888
A21: 9 | B21: =$B$7^(MIN(A21,$B$9)-1)*$B$8^(MAX(A21-$B$9,0)) -> 6.3125647 | C21: =$B$8^(A21-1) -> 9.2170395 | D21: 1.1 | E21: =E20*D21 -> 12968.712 | F21: =F20*$D21 -> 7073.8431 | G21: =G20*$D21 -> 7073.8431 | H21: =H20*$D21 -> 5894.8692 | I21: =I20*$D21 -> 5894.8692 | J21: =J20*$D21 -> 5894.8692 | K21: =K20*$D21 -> 5894.8692 | L21: =L20*$D21 -> 4715.8954 | M21: =M20*$D21 -> 3536.9215 | ... O21: =O20*$D21 -> 2357.9477
A22: 10 | B22: =$B$7^(MIN(A22,$B$9)-1)*$B$8^(MAX(A22-$B$9,0)) -> 7.9475189 | C22: =$B$8^(A22-1) -> 12.166492 | D22: 1.1 | E22: =E21*D22 -> 14265.584 | F22: =F21*$D22 -> 7781.2274 | G22: =G21*$D22 -> 7781.2274 | H22: =H21*$D22 -> 6484.3562 | I22: =I21*$D22 -> 6484.3562 | J22: =J21*$D22 -> 6484.3562 | K22: =K21*$D22 -> 6484.3562 | L22: =L21*$D22 -> 5187.4849 | M22: =M21*$D22 -> 3890.6137 | ... O22: =O21*$D22 -> 2593.7425
A23: 11 | B23: =$B$7^(MIN(A23,$B$9)-1)*$B$8^(MAX(A23-$B$9,0)) -> 10.005926 | C23: =$B$8^(A23-1) -> 16.05977 | D23: 1.1 | E23: =E22*D23 -> 15692.142 | F23: =F22*$D23 -> 8559.3501 | G23: =G22*$D23 -> 8559.3501 | H23: =H22*$D23 -> 7132.7918 | I23: =I22*$D23 -> 7132.7918 | J23: =J22*$D23 -> 7132.7918 | K23: =K22*$D23 -> 7132.7918 | L23: =L22*$D23 -> 5706.2334 | M23: =M22*$D23 -> 4279.6751 | ... O23: =O22*$D23 -> 2853.1167
A24: 12 | B24: =$B$7^(MIN(A24,$B$9)-1)*$B$8^(MAX(A24-$B$9,0)) -> 12.597461 | C24: =$B$8^(A24-1) -> 21.198896 | D24: 1.1 | E24: =E23*D24 -> 17261.356 | F24: =F23*$D24 -> 9415.2851 | G24: =G23*$D24 -> 9415.2851 | H24: =H23*$D24 -> 7846.0709 | I24: =I23*$D24 -> 7846.0709 | J24: =J23*$D24 -> 7846.0709 | K24: =K23*$D24 -> 7846.0709 | L24: =L23*$D24 -> 6276.8568 | M24: =M23*$D24 -> 4707.6426 | ... O24: =O23*$D24 -> 3138.4284
A25: 13 | B25: =$B$7^(MIN(A25,$B$9)-1)*$B$8^(MAX(A25-$B$9,0)) -> 16.628649 | C25: =$B$8^(A25-1) -> 27.982543 | D25: 1.1 | E25: =E24*D25 -> 18987.492 | F25: =F24*$D25 -> 10356.814 | G25: =G24*$D25 -> 10356.814 | H25: =H24*$D25 -> 8630.678 | I25: =I24*$D25 -> 8630.678 | J25: =J24*$D25 -> 8630.678 | K25: =K24*$D25 -> 8630.678 | L25: =L24*$D25 -> 6904.5424 | M25: =M24*$D25 -> 5178.4068 | ... O25: =O24*$D25 -> 3452.2712
A26: 14 | B26: =$B$7^(MIN(A26,$B$9)-1)*$B$8^(MAX(A26-$B$9,0)) -> 21.949816 | C26: =$B$8^(A26-1) -> 36.936956 | D26: 1.1 | E26: =E25*D26 -> 20886.241 | F26: =F25*$D26 -> 11392.495 | G26: =G25*$D26 -> 11392.495 | H26: =H25*$D26 -> 9493.7458 | I26: =I25*$D26 -> 9493.7458 | J26: =J25*$D26 -> 9493.7458 | K26: =K25*$D26 -> 9493.7458 | L26: =L25*$D26 -> 7594.9967 | M26: =M25*$D26 -> 5696.2475 | ... O26: =O25*$D26 -> 3797.4983
A27: 15 | B27: =$B$7^(MIN(A27,$B$9)-1)*$B$8^(MAX(A27-$B$9,0)) -> 28.973758 | C27: =$B$8^(A27-1) -> 48.756782 | D27: 1.1 | E27: =E26*D27 -> 22974.865 | F27: =F26*$D27 -> 12531.745 | G27: =G26*$D27 -> 12531.745 | H27: =H26*$D27 -> 10443.12 | I27: =I26*$D27 -> 10443.12 | J27: =J26*$D27 -> 10443.12 | K27: =K26*$D27 -> 10443.12 | L27: =L26*$D27 -> 8354.4963 | M27: =M26*$D27 -> 6265.8723 | ... O27: =O26*$D27 -> 4177.2482
A28: 16 | B28: =$B$7^(MIN(A28,$B$9)-1)*$B$8^(MAX(A28-$B$9,0)) -> 38.24536 | C28: =$B$8^(A28-1) -> 64.358953 | D28: 1.1 | E28: =E27*D28 -> 25272.351 | F28: =F27*$D28 -> 13784.919 | G28: =G27*$D28 -> 13784.919 | H28: =H27*$D28 -> 11487.432 | I28: =I27*$D28 -> 11487.432 | J28: =J27*$D28 -> 11487.432 | K28: =K27*$D28 -> 11487.432 | L28: =L27*$D28 -> 9189.946 | M28: =M27*$D28 -> 6892.4595 | ... O28: =O27*$D28 -> 4594.973
... A62: 50 | B62: =$B$7^(MIN(A62,$B$9)-1)*$B$8^(MAX(A62-$B$9,0)) -> 480941.68 | C62: =$B$8^(A62-1) -> 809324.39 | D62: 1.1 | E62: =E61*D62 -> 645649.69 | F62: =F61*$D62 -> 352172.56 | G62: =G61*$D62 -> 352172.56 | H62: =H61*$D62 -> 293477.13 | I62: =I61*$D62 -> 293477.13 | J62: =J61*$D62 -> 293477.13 | K62: =K61*$D62 -> 293477.13 | L62: =L61*$D62 -> 234781.71 | M62: =M61*$D62 -> 176086.28 | ... O62: =O61*$D62 -> 117390.85
B63: =$B$7^(MIN(A63,$B$9)-1)*$B$8^(MAX(A63-$B$9,0)) -> 12.597461
A64: · Les PV de niveau 1 viennent de l'onglet BATIMENTS, donc de RELEVE-TA-COURBES-2.md §6.5 : ce sont les valeurs de Tiberium Alliances, transposées et non arbitrées.
A65: · L'écart entre les deux régimes n'est pas cosmétique. COURBE-DE-NIVEAU-2.md §3 : à ×1,32 partout, un site de niveau 12 a 1,6 fois plus de PV que son butin ne le justifie, et l'écart reste acquis ensuite.
A66: · La propriété du miroir — un niveau 30 contre son miroir se comporte comme un niveau 50 contre le sien — tient dans les DEUX cas. Elle ne tranche pas la question.
A67: · ⚠ Ces nombres deviennent énormes : au niveau 50, deux régimes donnent ×480 942. C'est la cause des deux débordements arithmétiques de COURBE-DE-NIVEAU-2.md §5 et §7.

Sheet TROUS
A1: Ce qui manque, et ce que chaque trou bloque
A2: Aucun ne bloque le code qui tourne aujourd'hui. Tous bloquent quelque chose plus loin.
A4: # | B4: Donnée manquante | C4: Ce qu'elle bloque | D4: Ce qui existe déjà | E4: Source de la question
A5: 1 | B5: Coût de construction de chaque bâtiment, niveau 1 | C5: toute la progression : sans coût, aucune décision de base n'a d'enjeu | D5: la COURBE de montée (×1,32) est acquise ; l'ancrage ne l'est pas | E5: MODELE-REPARATION-1.md §6.7
A6: 2 | B6: Coût de montée, ancrage par bâtiment | C6: la campagne, la progression | D6: coût(n→n+1) = base × 1,32^(n−11) pour n ≥ 11 — RELEVE-TA-COURBES-2.md §5 | E6: MODELE-REPARATION-1.md §6.7
A7: 3 | B7: Coût de réparation des bâtiments et des unités | C7: la campagne — c'est le vrai facteur limitant | D7: le TEMPS est mesuré : T(L,C) au §4 du relevé. Seul le coût manque | E7: MODELE-REPARATION-1.md §3 et §6.7
A8: 4 | B8: Électricité : production par centrale | C8: la base du joueur, et par ricochet toutes les améliorations | D8: l'intention est arbitrée : 4e grandeur, non pillable, conditionne TOUT | E8: BASE-DU-JOUEUR-1.md §4
A9: 5 | B9: Électricité : coût par amélioration | C9: la progression entière | D9: chez TA, le quart de la monnaie principale — RELEVE-TA-COURBES-2.md §5 | E9: BASE-DU-JOUEUR-1.md §4
A10: 6 | B10: Électricité : plafonds de stockage | C10: l'équilibre production / dépense | D10: TA : 15 à l'Accumulateur, 40 au Chantier | E10: BASE-DU-JOUEUR-1.md §4
A11: 7 | B11: Voisinage TYPÉ : rayon, bonus par voisin, plafond | C11: l'intérêt même de la disposition de la base | D11: le socle non typé existe — params.js, adjacence 0,5 × P(1), 2 voisins | E11: BASE-DU-JOUEUR-1.md §3
A12: 8 | B12: Réserve de temps de réparation : 5e grandeur ou compteur interne ? | C12: la campagne | D12: le principe est arbitré : elle s'accumule, base et unités y puisent ensemble | E12: MODELE-REPARATION-1.md §4 et §6.4
A13: 9 | B13: Réserve de temps : taux d'accumulation, plafond | C13: la campagne | D13: rien | E13: MODELE-REPARATION-1.md §6.4
A14: 10 | B14: Formule du dépassement de l'heure quand les défenses passent le Complexe | C14: l'arbitrage puissance / disponibilité du QG contre le Complexe | D14: le principe : jamais moins d'une heure, davantage si les défenses dépassent | E14: MODELE-REPARATION-1.md §3 et §6.6
A15: 11 | B15: Plafond de niveau : le Centre de commandement et le QG le fixent — comment ? | C15: la calibration du combat, où +1 niveau vaut ×1,74 | D15: chez TA : plafond = niveau du bâtiment | E15: SPEC-FOYER-ZERO.md §7
A16: 12 | B16: Nom Foyer Zéro du central du joueur, et du bâtiment des blindés | C16: l'affichage — « Chantier de construction » est un nom TA | D16: côté Ouvrage il s'appelle Souche ; le bâtiment des blindés est dit « dépôt de véhicules » | E16: MODELE-REPARATION-1.md §6.3, BASE-DU-JOUEUR-1.md §2
... A18: 14 | B18: Un ou deux régimes pour les PV, et rupture au niveau 11 ou 12 ? | C18: la calibration de l'économie et le rapport butin / PV détruit | D18: recommandation écrite : les deux régimes, comme le butin et les coûts | E18: COURBE-DE-NIVEAU-2.md §3, RELEVE-TA-COURBES-2.md §5
B20: 14 trous. Les six premiers sont des barèmes : ils se remplissent a posteriori et se modifient sans rien casser. Les cinq derniers sont des questions de conception : ils décident de ce qu'on code.
